Workbook
Name Wt_security: 'Rubric'!$C$17
Name Wt_revenue: 'Rubric'!$C$18
Name Wt_mission: 'Rubric'!$C$19
Name Wt_analytics: 'Rubric'!$C$20
Name Wt_technical: 'Rubric'!$C$21
Name Wt_foundational: 'Rubric'!$C$22
Name Wt_search: 'Rubric'!$C$23
Name Wt_content: 'Rubric'!$C$24
Name CategoryWeights: 'Rubric'!$C$17:$C$24
Name SubWt_security: 'Rubric'!$C$30:$C$36
Name SubWt_revenue: 'Rubric'!$C$40:$C$42
Name SubWt_mission: 'Rubric'!$C$46:$C$48
Name SubWt_analytics: 'Rubric'!$C$52:$C$54
Name SubWt_technical: 'Rubric'!$C$58:$C$60
Name SubWt_foundational: 'Rubric'!$C$64:$C$66
Name SubWt_search: 'Rubric'!$C$70:$C$72
Name SubWt_content: 'Rubric'!$C$76:$C$78
Name GradeTable: 'Rubric'!$A$83:$B$92
Name SecurityOverrideEnabled: 'Rubric'!$B$96
Name SecurityOverrideCapPct: 'Rubric'!$B$97

Sheet Cover
A3: Website Auditor - Audit Scorecard
A4: Prepared by Legion Code Inc.
B6: Auditor | C6: {{auditor_name}}
B7: Audited party contact | C7: {{contact_name}}
B8: Audited party business | C8: {{business_name}}
B9: Domain | C9: {{website_url}}
B10: Engagement reference | C10: {{engagement_ref}}
B11: Report date | C11: {{report_date}}
B12: Template generated | C12: 2026-08-18 21:18 UTC
B13: Template generator | C13: generate-scorecard-xlsx.py (audit-scoring-stinger)
B16: {{...}} placeholders are hydrated by audit-intake-worker-bee's four recorded answers and by audit-scoring-worker-bee at rollup time. This Cover sheet carries no formulas; it is populated by direct cell write, per the template-injection pattern in references/research/distilled-audit-scoring.md section 3.
A22: Audit tool created by Legion Code Inc. | [LOGO PLACEHOLDER: Legion Code Inc. mark] | https://legioncodeinc.com (placeholder URL, see brand.json note - real brand assets not yet vendored into this repo)

Sheet Executive Scorecard
A1: Executive Scorecard
A2: Final grade, per-category rollups, and the critical-security-override banner.
A4: Category | B4: Weight | C4: Rollup % | D4: Contribution
A5: Security | B5: =Wt_security | C5: =Scorecard!L55 | D5: =B5*C5
A6: Revenue Drivers | B6: =Wt_revenue | C6: =Scorecard!L79 | D6: =B6*C6
A7: Mission Critical | B7: =Wt_mission | C7: =Scorecard!L103 | D7: =B7*C7
A8: Analytics and Insight | B8: =Wt_analytics | C8: =Scorecard!L127 | D8: =B8*C8
A9: Technical Deployment | B9: =Wt_technical | C9: =Scorecard!L151 | D9: =B9*C9
A10: Foundational Completeness | B10: =Wt_foundational | C10: =Scorecard!L175 | D10: =B10*C10
A11: Search Presence | B11: =Wt_search | C11: =Scorecard!L199 | D11: =B11*C11
A12: Content Score | B12: =Wt_content | C12: =Scorecard!L223 | D12: =B12*C12
A14: FINAL SCORE (raw, before override) | C14: =SUMPRODUCT(C5:C12,CategoryWeights)/SUM(CategoryWeights)
A16: Critical security override active? | C16: =IF(AND(SecurityOverrideEnabled,COUNTIFS(Scorecard!$E$5:$E$55,1)>0),TRUE,FALSE)
A17: Triggering finding (leaf ID) | C17: =IFERROR(INDEX(Scorecard!$C$5:$C$55,MATCH(1,Scorecard!$M$5:$M$55,0)),"")
A18: Triggering finding (description) | C18: =IFERROR(INDEX(Scorecard!$D$5:$D$55,MATCH(1,Scorecard!$M$5:$M$55,0)),"")
A20: Effective % (capped if override active) | C20: =IF(C16,MIN(C14,SecurityOverrideCapPct),C14)
A22: FINAL LETTER GRADE | C22: =VLOOKUP(C20,GradeTable,2,TRUE)
A24: =IF(C16,"CRITICAL SECURITY OVERRIDE ACTIVE - final grade capped at "&VLOOKUP(SecurityOverrideCapPct,GradeTable,2,TRUE)&". Triggering finding: "&C17&" - "&C18,"No critical security override active.")
A28: Audit tool created by Legion Code Inc. | [LOGO PLACEHOLDER: Legion Code Inc. mark] | https://legioncodeinc.com (placeholder URL, see brand.json note - real brand assets not yet vendored into this repo)

Sheet Rubric
A1: Rubric - Scoring Configuration
A2: Every weight used by every formula in this workbook lives here as a named range. Retune here; never edit a formula.
A4: 0-6 Leaf Scale
A5: Value | B5: Grade | C5: Band | D5: Definition
A6: 0 | B6: N/A | C6: no-op | D6: Audit point not relevant to this site type. Excluded from both numerator and denominator. Never counts as a failure.
A7: 1 | B7: F | C7: Critical | D7: Absent entirely, or present and critically failing. Blocks revenue, exposes risk, or breaks the function it exists to serve.
A8: 2 | B8: D | C8: High | D8: Present but materially broken. Works in some cases and fails in common ones.
A9: 3 | B9: C | C9: Medium | D9: Present and meets baseline. Low-severity findings only. Does the job without doing it well.
A10: 4 | B10: B minus | C10: Low | D10: Solid implementation. Minor findings a specialist would notice and a customer would not.
A11: 5 | B11: B | C11: Cosmetic | D11: Strong. Only cosmetic or preference-level findings remain.
A12: 6 | B12: A | C12: None | D12: Complete. Zero findings low through critical. Meets or exceeds the current published standard for this checkpoint.
A15: Category Weights (points, sums to 100)
A16: Rank | B16: Category | C16: Weight | D16: Named range | E16: Check
A17: 1 | B17: Security | C17: 20 | D17: Wt_security
A18: 2 | B18: Revenue Drivers | C18: 18 | D18: Wt_revenue
A19: 3 | B19: Mission Critical | C19: 14 | D19: Wt_mission
A20: 4 | B20: Analytics and Insight | C20: 12 | D20: Wt_analytics
A21: 5 | B21: Technical Deployment | C21: 11 | D21: Wt_technical
A22: 6 | B22: Foundational Completeness | C22: 10 | D22: Wt_foundational
A23: 7 | B23: Search Presence | C23: 9 | D23: Wt_search
A24: 8 | B24: Content Score | C24: 6 | D24: Wt_content
B25: Check: should equal 100 | C25: =SUM(C17:C24)
A28: Sub-audit Weights (per category; self-normalizing, do not need to sum to the category weight)
A29: Security
B30: Headers | C30: 2.8571
B31: TLS | C31: 2.8571
B32: Cookies | C32: 2.8571
B33: Content-Security-Policy | C33: 2.8571
B34: Platform Exposure | C34: 2.8571
B35: Client-Side Injection | C35: 2.8571
B36: Payment-Path Integrity | C36: 2.8571
B37: Named range: SubWt_security
A39: Revenue Drivers
B40: Visual UX/UI | C40: 7
B41: Navigation & User Journey | C41: 6
B42: On-Page Copy | C42: 5
B43: Named range: SubWt_revenue
A45: Mission Critical
B46: Primary Conversion Path Integrity | C46: 4.6667
B47: Core Function Reliability | C47: 4.6667
...

Sheet Scorecard
A1: Scorecard - Leaf to Sub-audit to Category Rollup
A2: N/A-aware masked SUMPRODUCT at every level. Column L carries every rollup value; column E carries only real leaf scores.
A4: Category | B4: Sub-audit | C4: Leaf ID | D4: Description | E4: Score (0-6) | F4: Evidence pointer | G4: Justification | H4: Weight | I4: Included? | J4: Row type | L4: Rollup %
A5: Security | C5: Weight: 20 pts (='Rubric'!$C$17) | J5: Category Header
B6: Headers (weight 2.8571) | J6: Sub-audit Header
A7: Security | B7: Headers | C7: SECURITY-HEADERS-01 | D7: Example: Strict-Transport-Security header absent (illustrative - demonstrates the override firing) | E7: 1 | F7: example-evidence-pointer.md#L1 | G7: Illustrative justification text. | H7: 1 | I7: =IF(E7="","",IF(E7>0,"Included","Excluded (N/A)")) | J7: Leaf | M7: =IF(E7=1,1,0)
A8: Security | B8: Headers | C8: SECURITY-HEADERS-02 | D8: Example leaf 2 for Headers (illustrative placeholder - replaced by the real upstream Bee's finding at run time) | E8: 6 | F8: example-evidence-pointer.md#L1 | G8: Illustrative justification text. | H8: 1 | I8: =IF(E8="","",IF(E8>0,"Included","Excluded (N/A)")) | J8: Leaf | M8: =IF(E8=1,1,0)
A9: Security | B9: Headers | C9: SECURITY-HEADERS-03 | D9: Example leaf 3 for Headers (illustrative placeholder - replaced by the real upstream Bee's finding at run time) | E9: 6 | F9: example-evidence-pointer.md#L1 | G9: Illustrative justification text. | H9: 1 | I9: =IF(E9="","",IF(E9>0,"Included","Excluded (N/A)")) | J9: Leaf | M9: =IF(E9=1,1,0)
A10: Security | B10: Headers | C10: SECURITY-HEADERS-04 | D10: Example leaf 4 for Headers (illustrative - not applicable to this site type) | E10: 0 | F10: n/a | G10: Not applicable to this site type. | H10: 1 | I10: =IF(E10="","",IF(E10>0,"Included","Excluded (N/A)")) | J10: Leaf | M10: =IF(E10=1,1,0)
B11: -> Headers rollup | J11: Sub-audit Rollup | L11: =IF(SUMPRODUCT(--(E7:E10>0),H7:H10)=0,"N/A",SUMPRODUCT(--(E7:E10>0),E7:E10,H7:H10)/(6*SUMPRODUCT(--(E7:E10>0),H7:H10)))
B12: TLS (weight 2.8571) | J12: Sub-audit Header
A13: Security | B13: TLS | C13: SECURITY-TLS-01 | D13: Example leaf 1 for TLS (illustrative placeholder - replaced by the real upstream Bee's finding at run time) | E13: 6 | F13: example-evidence-pointer.md#L1 | G13: Illustrative justification text. | H13: 1 | I13: =IF(E13="","",IF(E13>0,"Included","Excluded (N/A)")) | J13: Leaf | M13: =IF(E13=1,1,0)
A14: Security | B14: TLS | C14: SECURITY-TLS-02 | D14: Example leaf 2 for TLS (illustrative placeholder - replaced by the real upstream Bee's finding at run time) | E14: 6 | F14: example-evidence-pointer.md#L1 | G14: Illustrative justification text. | H14: 1 | I14: =IF(E14="","",IF(E14>0,"Included","Excluded (N/A)")) | J14: Leaf | M14: =IF(E14=1,1,0)
A15: Security | B15: TLS | C15: SECURITY-TLS-03 | D15: Example leaf 3 for TLS (illustrative placeholder - replaced by the real upstream Bee's finding at run time) | E15: 6 | F15: example-evidence-pointer.md#L1 | G15: Illustrative justification text. | H15: 1 | I15: =IF(E15="","",IF(E15>0,"Included","Excluded (N/A)")) | J15: Leaf | M15: =IF(E15=1,1,0)
A16: Security | B16: TLS | C16: SECURITY-TLS-04 | D16: Example leaf 4 for TLS (illustrative - not applicable to this site type) | E16: 0 | F16: n/a | G16: Not applicable to this site type. | H16: 1 | I16: =IF(E16="","",IF(E16>0,"Included","Excluded (N/A)")) | J16: Leaf | M16: =IF(E16=1,1,0)
B17: -> TLS rollup | J17: Sub-audit Rollup | L17: =IF(SUMPRODUCT(--(E13:E16>0),H13:H16)=0,"N/A",SUMPRODUCT(--(E13:E16>0),E13:E16,H13:H16)/(6*SUMPRODUCT(--(E13:E16>0),H13:H16)))
B18: Cookies (weight 2.8571) | J18: Sub-audit Header
A19: Security | B19: Cookies | C19: SECURITY-COOKIES-01 | D19: Example leaf 1 for Cookies (illustrative placeholder - replaced by the real upstream Bee's finding at run time) | E19: 6 | F19: example-evidence-pointer.md#L1 | G19: Illustrative justification text. | H19: 1 | I19: =IF(E19="","",IF(E19>0,"Included","Excluded (N/A)")) | J19: Leaf | M19: =IF(E19=1,1,0)
A20: Security | B20: Cookies | C20: SECURITY-COOKIES-02 | D20: Example leaf 2 for Cookies (illustrative placeholder - replaced by the real upstream Bee's finding at run time) | E20: 6 | F20: example-evidence-pointer.md#L1 | G20: Illustrative justification text. | H20: 1 | I20: =IF(E20="","",IF(E20>0,"Included","Excluded (N/A)")) | J20: Leaf | M20: =IF(E20=1,1,0)
A21: Security | B21: Cookies | C21: SECURITY-COOKIES-03 | D21: Example leaf 3 for Cookies (illustrative placeholder - replaced by the real upstream Bee's finding at run time) | E21: 6 | F21: example-evidence-pointer.md#L1 | G21: Illustrative justification text. | H21: 1 | I21: =IF(E21="","",IF(E21>0,"Included","Excluded (N/A)")) | J21: Leaf | M21: =IF(E21=1,1,0)
A22: Security | B22: Cookies | C22: SECURITY-COOKIES-04 | D22: Example leaf 4 for Cookies (illustrative - not applicable to this site type) | E22: 0 | F22: n/a | G22: Not applicable to this site type. | H22: 1 | I22: =IF(E22="","",IF(E22>0,"Included","Excluded (N/A)")) | J22: Leaf | M22: =IF(E22=1,1,0)
B23: -> Cookies rollup | J23: Sub-audit Rollup | L23: =IF(SUMPRODUCT(--(E19:E22>0),H19:H22)=0,"N/A",SUMPRODUCT(--(E19:E22>0),E19:E22,H19:H22)/(6*SUMPRODUCT(--(E19:E22>0),H19:H22)))
B24: Content-Security-Policy (weight 2.8571) | J24: Sub-audit Header
A25: Security | B25: Content-Security-Policy | C25: SECURITY-CSP-01 | D25: Example leaf 1 for Content-Security-Policy (illustrative placeholder - replaced by the real upstream Bee's finding at run time) | E25: 6 | F25: example-evidence-pointer.md#L1 | G25: Illustrative justification text. | H25: 1 | I25: =IF(E25="","",IF(E25>0,"Included","Excluded (N/A)")) | J25: Leaf | M25: =IF(E25=1,1,0)
A26: Security | B26: Content-Security-Policy | C26: SECURITY-CSP-02 | D26: Example leaf 2 for Content-Security-Policy (illustrative placeholder - replaced by the real upstream Bee's finding at run time) | E26: 6 | F26: example-evidence-pointer.md#L1 | G26: Illustrative justification text. | H26: 1 | I26: =IF(E26="","",IF(E26>0,"Included","Excluded (N/A)")) | J26: Leaf | M26: =IF(E26=1,1,0)
A27: Security | B27: Content-Security-Policy | C27: SECURITY-CSP-03 | D27: Example leaf 3 for Content-Security-Policy (illustrative placeholder - replaced by the real upstream Bee's finding at run time) | E27: 6 | F27: example-evidence-pointer.md#L1 | G27: Illustrative justification text. | H27: 1 | I27: =IF(E27="","",IF(E27>0,"Included","Excluded (N/A)")) | J27: Leaf | M27: =IF(E27=1,1,0)
A28: Security | B28: Content-Security-Policy | C28: SECURITY-CSP-04 | D28: Example leaf 4 for Content-Security-Policy (illustrative - not applicable to this site type) | E28: 0 | F28: n/a | G28: Not applicable to this site type. | H28: 1 | I28: =IF(E28="","",IF(E28>0,"Included","Excluded (N/A)")) | J28: Leaf | M28: =IF(E28=1,1,0)
B29: -> Content-Security-Policy rollup | J29: Sub-audit Rollup | L29: =IF(SUMPRODUCT(--(E25:E28>0),H25:H28)=0,"N/A",SUMPRODUCT(--(E25:E28>0),E25:E28,H25:H28)/(6*SUMPRODUCT(--(E25:E28>0),H25:H28)))
B30: Platform Exposure (weight 2.8571) | J30: Sub-audit Header
A31: Security | B31: Platform Exposure | C31: SECURITY-PLATFORM_EXPOSURE-01 | D31: Example leaf 1 for Platform Exposure (illustrative placeholder - replaced by the real upstream Bee's finding at run time) | E31: 6 | F31: example-evidence-pointer.md#L1 | G31: Illustrative justification text. | H31: 1 | I31: =IF(E31="","",IF(E31>0,"Included","Excluded (N/A)")) | J31: Leaf | M31: =IF(E31=1,1,0)
A32: Security | B32: Platform Exposure | C32: SECURITY-PLATFORM_EXPOSURE-02 | D32: Example leaf 2 for Platform Exposure (illustrative placeholder - replaced by the real upstream Bee's finding at run time) | E32: 6 | F32: example-evidence-pointer.md#L1 | G32: Illustrative justification text. | H32: 1 | I32: =IF(E32="","",IF(E32>0,"Included","Excluded (N/A)")) | J32: Leaf | M32: =IF(E32=1,1,0)
A33: Security | B33: Platform Exposure | C33: SECURITY-PLATFORM_EXPOSURE-03 | D33: Example leaf 3 for Platform Exposure (illustrative placeholder - replaced by the real upstream Bee's finding at run time) | E33: 6 | F33: example-evidence-pointer.md#L1 | G33: Illustrative justification text. | H33: 1 | I33: =IF(E33="","",IF(E33>0,"Included","Excluded (N/A)")) | J33: Leaf | M33: =IF(E33=1,1,0)
A34: Security | B34: Platform Exposure | C34: SECURITY-PLATFORM_EXPOSURE-04 | D34: Example leaf 4 for Platform Exposure (illustrative - not applicable to this site type) | E34: 0 | F34: n/a | G34: Not applicable to this site type. | H34: 1 | I34: =IF(E34="","",IF(E34>0,"Included","Excluded (N/A)")) | J34: Leaf | M34: =IF(E34=1,1,0)
B35: -> Platform Exposure rollup | J35: Sub-audit Rollup | L35: =IF(SUMPRODUCT(--(E31:E34>0),H31:H34)=0,"N/A",SUMPRODUCT(--(E31:E34>0),E31:E34,H31:H34)/(6*SUMPRODUCT(--(E31:E34>0),H31:H34)))
B36: Client-Side Injection (weight 2.8571) | J36: Sub-audit Header
A37: Security | B37: Client-Side Injection | C37: SECURITY-CLIENT_INJECTION-01 | D37: Example leaf 1 for Client-Side Injection (illustrative placeholder - replaced by the real upstream Bee's finding at run time) | E37: 6 | F37: example-evidence-pointer.md#L1 | G37: Illustrative justification text. | H37: 1 | I37: =IF(E37="","",IF(E37>0,"Included","Excluded (N/A)")) | J37: Leaf | M37: =IF(E37=1,1,0)
A38: Security | B38: Client-Side Injection | C38: SECURITY-CLIENT_INJECTION-02 | D38: Example leaf 2 for Client-Side Injection (illustrative placeholder - replaced by the real upstream Bee's finding at run time) | E38: 6 | F38: example-evidence-pointer.md#L1 | G38: Illustrative justification text. | H38: 1 | I38: =IF(E38="","",IF(E38>0,"Included","Excluded (N/A)")) | J38: Leaf | M38: =IF(E38=1,1,0)
A39: Security | B39: Client-Side Injection | C39: SECURITY-CLIENT_INJECTION-03 | D39: Example leaf 3 for Client-Side Injection (illustrative placeholder - replaced by the real upstream Bee's finding at run time) | E39: 6 | F39: example-evidence-pointer.md#L1 | G39: Illustrative justification text. | H39: 1 | I39: =IF(E39="","",IF(E39>0,"Included","Excluded (N/A)")) | J39: Leaf | M39: =IF(E39=1,1,0)
A40: Security | B40: Client-Side Injection | C40: SECURITY-CLIENT_INJECTION-04 | D40: Example leaf 4 for Client-Side Injection (illustrative - not applicable to this site type) | E40: 0 | F40: n/a | G40: Not applicable to this site type. | H40: 1 | I40: =IF(E40="","",IF(E40>0,"Included","Excluded (N/A)")) | J40: Leaf | M40: =IF(E40=1,1,0)
B41: -> Client-Side Injection rollup | J41: Sub-audit Rollup | L41: =IF(SUMPRODUCT(--(E37:E40>0),H37:H40)=0,"N/A",SUMPRODUCT(--(E37:E40>0),E37:E40,H37:H40)/(6*SUMPRODUCT(--(E37:E40>0),H37:H40)))
...

Sheet Audit Tree
A2: Audit Tree
B4: This template consolidates the full leaf -> sub-audit -> category hierarchy into the 'Scorecard' sheet rather than duplicating it on a second sheet, so there is exactly one place the rollup formulas live and one place to audit them. This sheet name exists to satisfy build plan section 4.4's sheet inventory; its content is the design decision, documented in guides/03-nesting-structure-design.md, not an omission. Go to 'Scorecard' for the full hierarchy, every leaf, its score, weight, evidence pointer, and justification.
A12: Audit tool created by Legion Code Inc. | [LOGO PLACEHOLDER: Legion Code Inc. mark] | https://legioncodeinc.com (placeholder URL, see brand.json note - real brand assets not yet vendored into this repo)

Sheet Security
A1: Security - Detail View
A2: Live-linked view of Scorecard rows 5-55. Edit scores on 'Scorecard'; this sheet mirrors, it does not recompute.
A4: Category | B4: Sub-audit | C4: Leaf ID | D4: Description | E4: Score (0-6) | F4: Evidence pointer | G4: Justification | H4: Weight | I4: Included? | J4: Row type | L4: Rollup %
A5: =Scorecard!A5 | B5: =Scorecard!B5 | C5: =Scorecard!C5 | D5: =Scorecard!D5 | E5: =Scorecard!E5 | F5: =Scorecard!F5 | G5: =Scorecard!G5 | H5: =Scorecard!H5 | ... L5: =Scorecard!L5
A6: =Scorecard!A6 | B6: =Scorecard!B6 | C6: =Scorecard!C6 | D6: =Scorecard!D6 | E6: =Scorecard!E6 | F6: =Scorecard!F6 | G6: =Scorecard!G6 | H6: =Scorecard!H6 | ... L6: =Scorecard!L6
A7: =Scorecard!A7 | B7: =Scorecard!B7 | C7: =Scorecard!C7 | D7: =Scorecard!D7 | E7: =Scorecard!E7 | F7: =Scorecard!F7 | G7: =Scorecard!G7 | H7: =Scorecard!H7 | ... L7: =Scorecard!L7
A8: =Scorecard!A8 | B8: =Scorecard!B8 | C8: =Scorecard!C8 | D8: =Scorecard!D8 | E8: =Scorecard!E8 | F8: =Scorecard!F8 | G8: =Scorecard!G8 | H8: =Scorecard!H8 | ... L8: =Scorecard!L8
A9: =Scorecard!A9 | B9: =Scorecard!B9 | C9: =Scorecard!C9 | D9: =Scorecard!D9 | E9: =Scorecard!E9 | F9: =Scorecard!F9 | G9: =Scorecard!G9 | H9: =Scorecard!H9 | ... L9: =Scorecard!L9
A10: =Scorecard!A10 | B10: =Scorecard!B10 | C10: =Scorecard!C10 | D10: =Scorecard!D10 | E10: =Scorecard!E10 | F10: =Scorecard!F10 | G10: =Scorecard!G10 | H10: =Scorecard!H10 | ... L10: =Scorecard!L10
A11: =Scorecard!A11 | B11: =Scorecard!B11 | C11: =Scorecard!C11 | D11: =Scorecard!D11 | E11: =Scorecard!E11 | F11: =Scorecard!F11 | G11: =Scorecard!G11 | H11: =Scorecard!H11 | ... L11: =Scorecard!L11
A12: =Scorecard!A12 | B12: =Scorecard!B12 | C12: =Scorecard!C12 | D12: =Scorecard!D12 | E12: =Scorecard!E12 | F12: =Scorecard!F12 | G12: =Scorecard!G12 | H12: =Scorecard!H12 | ... L12: =Scorecard!L12
A13: =Scorecard!A13 | B13: =Scorecard!B13 | C13: =Scorecard!C13 | D13: =Scorecard!D13 | E13: =Scorecard!E13 | F13: =Scorecard!F13 | G13: =Scorecard!G13 | H13: =Scorecard!H13 | ... L13: =Scorecard!L13
A14: =Scorecard!A14 | B14: =Scorecard!B14 | C14: =Scorecard!C14 | D14: =Scorecard!D14 | E14: =Scorecard!E14 | F14: =Scorecard!F14 | G14: =Scorecard!G14 | H14: =Scorecard!H14 | ... L14: =Scorecard!L14
A15: =Scorecard!A15 | B15: =Scorecard!B15 | C15: =Scorecard!C15 | D15: =Scorecard!D15 | E15: =Scorecard!E15 | F15: =Scorecard!F15 | G15: =Scorecard!G15 | H15: =Scorecard!H15 | ... L15: =Scorecard!L15
A16: =Scorecard!A16 | B16: =Scorecard!B16 | C16: =Scorecard!C16 | D16: =Scorecard!D16 | E16: =Scorecard!E16 | F16: =Scorecard!F16 | G16: =Scorecard!G16 | H16: =Scorecard!H16 | ... L16: =Scorecard!L16
... A55: =Scorecard!A55 | B55: =Scorecard!B55 | C55: =Scorecard!C55 | D55: =Scorecard!D55 | E55: =Scorecard!E55 | F55: =Scorecard!F55 | G55: =Scorecard!G55 | H55: =Scorecard!H55 | ... L55: =Scorecard!L55
A57: Audit tool created by Legion Code Inc. | [LOGO PLACEHOLDER: Legion Code Inc. mark] | https://legioncodeinc.com (placeholder URL, see brand.json note - real brand assets not yet vendored into this repo)

Sheet Revenue Drivers
A1: Revenue Drivers - Detail View
A2: Live-linked view of Scorecard rows 57-79. Edit scores on 'Scorecard'; this sheet mirrors, it does not recompute.
A4: Category | B4: Sub-audit | C4: Leaf ID | D4: Description | E4: Score (0-6) | F4: Evidence pointer | G4: Justification | H4: Weight | I4: Included? | J4: Row type | L4: Rollup %
A5: =Scorecard!A57 | B5: =Scorecard!B57 | C5: =Scorecard!C57 | D5: =Scorecard!D57 | E5: =Scorecard!E57 | F5: =Scorecard!F57 | G5: =Scorecard!G57 | H5: =Scorecard!H57 | ... L5: =Scorecard!L57
A6: =Scorecard!A58 | B6: =Scorecard!B58 | C6: =Scorecard!C58 | D6: =Scorecard!D58 | E6: =Scorecard!E58 | F6: =Scorecard!F58 | G6: =Scorecard!G58 | H6: =Scorecard!H58 | ... L6: =Scorecard!L58
A7: =Scorecard!A59 | B7: =Scorecard!B59 | C7: =Scorecard!C59 | D7: =Scorecard!D59 | E7: =Scorecard!E59 | F7: =Scorecard!F59 | G7: =Scorecard!G59 | H7: =Scorecard!H59 | ... L7: =Scorecard!L59
A8: =Scorecard!A60 | B8: =Scorecard!B60 | C8: =Scorecard!C60 | D8: =Scorecard!D60 | E8: =Scorecard!E60 | F8: =Scorecard!F60 | G8: =Scorecard!G60 | H8: =Scorecard!H60 | ... L8: =Scorecard!L60
A9: =Scorecard!A61 | B9: =Scorecard!B61 | C9: =Scorecard!C61 | D9: =Scorecard!D61 | E9: =Scorecard!E61 | F9: =Scorecard!F61 | G9: =Scorecard!G61 | H9: =Scorecard!H61 | ... L9: =Scorecard!L61
A10: =Scorecard!A62 | B10: =Scorecard!B62 | C10: =Scorecard!C62 | D10: =Scorecard!D62 | E10: =Scorecard!E62 | F10: =Scorecard!F62 | G10: =Scorecard!G62 | H10: =Scorecard!H62 | ... L10: =Scorecard!L62
A11: =Scorecard!A63 | B11: =Scorecard!B63 | C11: =Scorecard!C63 | D11: =Scorecard!D63 | E11: =Scorecard!E63 | F11: =Scorecard!F63 | G11: =Scorecard!G63 | H11: =Scorecard!H63 | ... L11: =Scorecard!L63
A12: =Scorecard!A64 | B12: =Scorecard!B64 | C12: =Scorecard!C64 | D12: =Scorecard!D64 | E12: =Scorecard!E64 | F12: =Scorecard!F64 | G12: =Scorecard!G64 | H12: =Scorecard!H64 | ... L12: =Scorecard!L64
A13: =Scorecard!A65 | B13: =Scorecard!B65 | C13: =Scorecard!C65 | D13: =Scorecard!D65 | E13: =Scorecard!E65 | F13: =Scorecard!F65 | G13: =Scorecard!G65 | H13: =Scorecard!H65 | ... L13: =Scorecard!L65
A14: =Scorecard!A66 | B14: =Scorecard!B66 | C14: =Scorecard!C66 | D14: =Scorecard!D66 | E14: =Scorecard!E66 | F14: =Scorecard!F66 | G14: =Scorecard!G66 | H14: =Scorecard!H66 | ... L14: =Scorecard!L66
A15: =Scorecard!A67 | B15: =Scorecard!B67 | C15: =Scorecard!C67 | D15: =Scorecard!D67 | E15: =Scorecard!E67 | F15: =Scorecard!F67 | G15: =Scorecard!G67 | H15: =Scorecard!H67 | ... L15: =Scorecard!L67
A16: =Scorecard!A68 | B16: =Scorecard!B68 | C16: =Scorecard!C68 | D16: =Scorecard!D68 | E16: =Scorecard!E68 | F16: =Scorecard!F68 | G16: =Scorecard!G68 | H16: =Scorecard!H68 | ... L16: =Scorecard!L68
... A27: =Scorecard!A79 | B27: =Scorecard!B79 | C27: =Scorecard!C79 | D27: =Scorecard!D79 | E27: =Scorecard!E79 | F27: =Scorecard!F79 | G27: =Scorecard!G79 | H27: =Scorecard!H79 | ... L27: =Scorecard!L79
A29: Audit tool created by Legion Code Inc. | [LOGO PLACEHOLDER: Legion Code Inc. mark] | https://legioncodeinc.com (placeholder URL, see brand.json note - real brand assets not yet vendored into this repo)

Sheet Mission Critical
A1: Mission Critical - Detail View
A2: Live-linked view of Scorecard rows 81-103. Edit scores on 'Scorecard'; this sheet mirrors, it does not recompute.
A4: Category | B4: Sub-audit | C4: Leaf ID | D4: Description | E4: Score (0-6) | F4: Evidence pointer | G4: Justification | H4: Weight | I4: Included? | J4: Row type | L4: Rollup %
A5: =Scorecard!A81 | B5: =Scorecard!B81 | C5: =Scorecard!C81 | D5: =Scorecard!D81 | E5: =Scorecard!E81 | F5: =Scorecard!F81 | G5: =Scorecard!G81 | H5: =Scorecard!H81 | ... L5: =Scorecard!L81
A6: =Scorecard!A82 | B6: =Scorecard!B82 | C6: =Scorecard!C82 | D6: =Scorecard!D82 | E6: =Scorecard!E82 | F6: =Scorecard!F82 | G6: =Scorecard!G82 | H6: =Scorecard!H82 | ... L6: =Scorecard!L82
A7: =Scorecard!A83 | B7: =Scorecard!B83 | C7: =Scorecard!C83 | D7: =Scorecard!D83 | E7: =Scorecard!E83 | F7: =Scorecard!F83 | G7: =Scorecard!G83 | H7: =Scorecard!H83 | ... L7: =Scorecard!L83
A8: =Scorecard!A84 | B8: =Scorecard!B84 | C8: =Scorecard!C84 | D8: =Scorecard!D84 | E8: =Scorecard!E84 | F8: =Scorecard!F84 | G8: =Scorecard!G84 | H8: =Scorecard!H84 | ... L8: =Scorecard!L84
A9: =Scorecard!A85 | B9: =Scorecard!B85 | C9: =Scorecard!C85 | D9: =Scorecard!D85 | E9: =Scorecard!E85 | F9: =Scorecard!F85 | G9: =Scorecard!G85 | H9: =Scorecard!H85 | ... L9: =Scorecard!L85
A10: =Scorecard!A86 | B10: =Scorecard!B86 | C10: =Scorecard!C86 | D10: =Scorecard!D86 | E10: =Scorecard!E86 | F10: =Scorecard!F86 | G10: =Scorecard!G86 | H10: =Scorecard!H86 | ... L10: =Scorecard!L86
A11: =Scorecard!A87 | B11: =Scorecard!B87 | C11: =Scorecard!C87 | D11: =Scorecard!D87 | E11: =Scorecard!E87 | F11: =Scorecard!F87 | G11: =Scorecard!G87 | H11: =Scorecard!H87 | ... L11: =Scorecard!L87
A12: =Scorecard!A88 | B12: =Scorecard!B88 | C12: =Scorecard!C88 | D12: =Scorecard!D88 | E12: =Scorecard!E88 | F12: =Scorecard!F88 | G12: =Scorecard!G88 | H12: =Scorecard!H88 | ... L12: =Scorecard!L88
A13: =Scorecard!A89 | B13: =Scorecard!B89 | C13: =Scorecard!C89 | D13: =Scorecard!D89 | E13: =Scorecard!E89 | F13: =Scorecard!F89 | G13: =Scorecard!G89 | H13: =Scorecard!H89 | ... L13: =Scorecard!L89
A14: =Scorecard!A90 | B14: =Scorecard!B90 | C14: =Scorecard!C90 | D14: =Scorecard!D90 | E14: =Scorecard!E90 | F14: =Scorecard!F90 | G14: =Scorecard!G90 | H14: =Scorecard!H90 | ... L14: =Scorecard!L90
A15: =Scorecard!A91 | B15: =Scorecard!B91 | C15: =Scorecard!C91 | D15: =Scorecard!D91 | E15: =Scorecard!E91 | F15: =Scorecard!F91 | G15: =Scorecard!G91 | H15: =Scorecard!H91 | ... L15: =Scorecard!L91
A16: =Scorecard!A92 | B16: =Scorecard!B92 | C16: =Scorecard!C92 | D16: =Scorecard!D92 | E16: =Scorecard!E92 | F16: =Scorecard!F92 | G16: =Scorecard!G92 | H16: =Scorecard!H92 | ... L16: =Scorecard!L92
... A27: =Scorecard!A103 | B27: =Scorecard!B103 | C27: =Scorecard!C103 | D27: =Scorecard!D103 | E27: =Scorecard!E103 | F27: =Scorecard!F103 | G27: =Scorecard!G103 | H27: =Scorecard!H103 | ... L27: =Scorecard!L103
A29: Audit tool created by Legion Code Inc. | [LOGO PLACEHOLDER: Legion Code Inc. mark] | https://legioncodeinc.com (placeholder URL, see brand.json note - real brand assets not yet vendored into this repo)

Sheet Analytics and Insight
A1: Analytics and Insight - Detail View
A2: Live-linked view of Scorecard rows 105-127. Edit scores on 'Scorecard'; this sheet mirrors, it does not recompute.
A4: Category | B4: Sub-audit | C4: Leaf ID | D4: Description | E4: Score (0-6) | F4: Evidence pointer | G4: Justification | H4: Weight | I4: Included? | J4: Row type | L4: Rollup %
A5: =Scorecard!A105 | B5: =Scorecard!B105 | C5: =Scorecard!C105 | D5: =Scorecard!D105 | E5: =Scorecard!E105 | F5: =Scorecard!F105 | G5: =Scorecard!G105 | H5: =Scorecard!H105 | ... L5: =Scorecard!L105
A6: =Scorecard!A106 | B6: =Scorecard!B106 | C6: =Scorecard!C106 | D6: =Scorecard!D106 | E6: =Scorecard!E106 | F6: =Scorecard!F106 | G6: =Scorecard!G106 | H6: =Scorecard!H106 | ... L6: =Scorecard!L106
A7: =Scorecard!A107 | B7: =Scorecard!B107 | C7: =Scorecard!C107 | D7: =Scorecard!D107 | E7: =Scorecard!E107 | F7: =Scorecard!F107 | G7: =Scorecard!G107 | H7: =Scorecard!H107 | ... L7: =Scorecard!L107
A8: =Scorecard!A108 | B8: =Scorecard!B108 | C8: =Scorecard!C108 | D8: =Scorecard!D108 | E8: =Scorecard!E108 | F8: =Scorecard!F108 | G8: =Scorecard!G108 | H8: =Scorecard!H108 | ... L8: =Scorecard!L108
A9: =Scorecard!A109 | B9: =Scorecard!B109 | C9: =Scorecard!C109 | D9: =Scorecard!D109 | E9: =Scorecard!E109 | F9: =Scorecard!F109 | G9: =Scorecard!G109 | H9: =Scorecard!H109 | ... L9: =Scorecard!L109
A10: =Scorecard!A110 | B10: =Scorecard!B110 | C10: =Scorecard!C110 | D10: =Scorecard!D110 | E10: =Scorecard!E110 | F10: =Scorecard!F110 | G10: =Scorecard!G110 | H10: =Scorecard!H110 | ... L10: =Scorecard!L110
A11: =Scorecard!A111 | B11: =Scorecard!B111 | C11: =Scorecard!C111 | D11: =Scorecard!D111 | E11: =Scorecard!E111 | F11: =Scorecard!F111 | G11: =Scorecard!G111 | H11: =Scorecard!H111 | ... L11: =Scorecard!L111
A12: =Scorecard!A112 | B12: =Scorecard!B112 | C12: =Scorecard!C112 | D12: =Scorecard!D112 | E12: =Scorecard!E112 | F12: =Scorecard!F112 | G12: =Scorecard!G112 | H12: =Scorecard!H112 | ... L12: =Scorecard!L112
A13: =Scorecard!A113 | B13: =Scorecard!B113 | C13: =Scorecard!C113 | D13: =Scorecard!D113 | E13: =Scorecard!E113 | F13: =Scorecard!F113 | G13: =Scorecard!G113 | H13: =Scorecard!H113 | ... L13: =Scorecard!L113
A14: =Scorecard!A114 | B14: =Scorecard!B114 | C14: =Scorecard!C114 | D14: =Scorecard!D114 | E14: =Scorecard!E114 | F14: =Scorecard!F114 | G14: =Scorecard!G114 | H14: =Scorecard!H114 | ... L14: =Scorecard!L114
A15: =Scorecard!A115 | B15: =Scorecard!B115 | C15: =Scorecard!C115 | D15: =Scorecard!D115 | E15: =Scorecard!E115 | F15: =Scorecard!F115 | G15: =Scorecard!G115 | H15: =Scorecard!H115 | ... L15: =Scorecard!L115
A16: =Scorecard!A116 | B16: =Scorecard!B116 | C16: =Scorecard!C116 | D16: =Scorecard!D116 | E16: =Scorecard!E116 | F16: =Scorecard!F116 | G16: =Scorecard!G116 | H16: =Scorecard!H116 | ... L16: =Scorecard!L116
... A27: =Scorecard!A127 | B27: =Scorecard!B127 | C27: =Scorecard!C127 | D27: =Scorecard!D127 | E27: =Scorecard!E127 | F27: =Scorecard!F127 | G27: =Scorecard!G127 | H27: =Scorecard!H127 | ... L27: =Scorecard!L127
A29: Audit tool created by Legion Code Inc. | [LOGO PLACEHOLDER: Legion Code Inc. mark] | https://legioncodeinc.com (placeholder URL, see brand.json note - real brand assets not yet vendored into this repo)

Sheet Technical Deployment
A1: Technical Deployment - Detail View
A2: Live-linked view of Scorecard rows 129-151. Edit scores on 'Scorecard'; this sheet mirrors, it does not recompute.
A4: Category | B4: Sub-audit | C4: Leaf ID | D4: Description | E4: Score (0-6) | F4: Evidence pointer | G4: Justification | H4: Weight | I4: Included? | J4: Row type | L4: Rollup %
A5: =Scorecard!A129 | B5: =Scorecard!B129 | C5: =Scorecard!C129 | D5: =Scorecard!D129 | E5: =Scorecard!E129 | F5: =Scorecard!F129 | G5: =Scorecard!G129 | H5: =Scorecard!H129 | ... L5: =Scorecard!L129
A6: =Scorecard!A130 | B6: =Scorecard!B130 | C6: =Scorecard!C130 | D6: =Scorecard!D130 | E6: =Scorecard!E130 | F6: =Scorecard!F130 | G6: =Scorecard!G130 | H6: =Scorecard!H130 | ... L6: =Scorecard!L130
A7: =Scorecard!A131 | B7: =Scorecard!B131 | C7: =Scorecard!C131 | D7: =Scorecard!D131 | E7: =Scorecard!E131 | F7: =Scorecard!F131 | G7: =Scorecard!G131 | H7: =Scorecard!H131 | ... L7: =Scorecard!L131
A8: =Scorecard!A132 | B8: =Scorecard!B132 | C8: =Scorecard!C132 | D8: =Scorecard!D132 | E8: =Scorecard!E132 | F8: =Scorecard!F132 | G8: =Scorecard!G132 | H8: =Scorecard!H132 | ... L8: =Scorecard!L132
A9: =Scorecard!A133 | B9: =Scorecard!B133 | C9: =Scorecard!C133 | D9: =Scorecard!D133 | E9: =Scorecard!E133 | F9: =Scorecard!F133 | G9: =Scorecard!G133 | H9: =Scorecard!H133 | ... L9: =Scorecard!L133
A10: =Scorecard!A134 | B10: =Scorecard!B134 | C10: =Scorecard!C134 | D10: =Scorecard!D134 | E10: =Scorecard!E134 | F10: =Scorecard!F134 | G10: =Scorecard!G134 | H10: =Scorecard!H134 | ... L10: =Scorecard!L134
A11: =Scorecard!A135 | B11: =Scorecard!B135 | C11: =Scorecard!C135 | D11: =Scorecard!D135 | E11: =Scorecard!E135 | F11: =Scorecard!F135 | G11: =Scorecard!G135 | H11: =Scorecard!H135 | ... L11: =Scorecard!L135
A12: =Scorecard!A136 | B12: =Scorecard!B136 | C12: =Scorecard!C136 | D12: =Scorecard!D136 | E12: =Scorecard!E136 | F12: =Scorecard!F136 | G12: =Scorecard!G136 | H12: =Scorecard!H136 | ... L12: =Scorecard!L136
A13: =Scorecard!A137 | B13: =Scorecard!B137 | C13: =Scorecard!C137 | D13: =Scorecard!D137 | E13: =Scorecard!E137 | F13: =Scorecard!F137 | G13: =Scorecard!G137 | H13: =Scorecard!H137 | ... L13: =Scorecard!L137
A14: =Scorecard!A138 | B14: =Scorecard!B138 | C14: =Scorecard!C138 | D14: =Scorecard!D138 | E14: =Scorecard!E138 | F14: =Scorecard!F138 | G14: =Scorecard!G138 | H14: =Scorecard!H138 | ... L14: =Scorecard!L138
A15: =Scorecard!A139 | B15: =Scorecard!B139 | C15: =Scorecard!C139 | D15: =Scorecard!D139 | E15: =Scorecard!E139 | F15: =Scorecard!F139 | G15: =Scorecard!G139 | H15: =Scorecard!H139 | ... L15: =Scorecard!L139
A16: =Scorecard!A140 | B16: =Scorecard!B140 | C16: =Scorecard!C140 | D16: =Scorecard!D140 | E16: =Scorecard!E140 | F16: =Scorecard!F140 | G16: =Scorecard!G140 | H16: =Scorecard!H140 | ... L16: =Scorecard!L140
... A27: =Scorecard!A151 | B27: =Scorecard!B151 | C27: =Scorecard!C151 | D27: =Scorecard!D151 | E27: =Scorecard!E151 | F27: =Scorecard!F151 | G27: =Scorecard!G151 | H27: =Scorecard!H151 | ... L27: =Scorecard!L151
A29: Audit tool created by Legion Code Inc. | [LOGO PLACEHOLDER: Legion Code Inc. mark] | https://legioncodeinc.com (placeholder URL, see brand.json note - real brand assets not yet vendored into this repo)

Sheet Foundational Completeness
A1: Foundational Completeness - Detail View
A2: Live-linked view of Scorecard rows 153-175. Edit scores on 'Scorecard'; this sheet mirrors, it does not recompute.
A4: Category | B4: Sub-audit | C4: Leaf ID | D4: Description | E4: Score (0-6) | F4: Evidence pointer | G4: Justification | H4: Weight | I4: Included? | J4: Row type | L4: Rollup %
A5: =Scorecard!A153 | B5: =Scorecard!B153 | C5: =Scorecard!C153 | D5: =Scorecard!D153 | E5: =Scorecard!E153 | F5: =Scorecard!F153 | G5: =Scorecard!G153 | H5: =Scorecard!H153 | ... L5: =Scorecard!L153
A6: =Scorecard!A154 | B6: =Scorecard!B154 | C6: =Scorecard!C154 | D6: =Scorecard!D154 | E6: =Scorecard!E154 | F6: =Scorecard!F154 | G6: =Scorecard!G154 | H6: =Scorecard!H154 | ... L6: =Scorecard!L154
A7: =Scorecard!A155 | B7: =Scorecard!B155 | C7: =Scorecard!C155 | D7: =Scorecard!D155 | E7: =Scorecard!E155 | F7: =Scorecard!F155 | G7: =Scorecard!G155 | H7: =Scorecard!H155 | ... L7: =Scorecard!L155
A8: =Scorecard!A156 | B8: =Scorecard!B156 | C8: =Scorecard!C156 | D8: =Scorecard!D156 | E8: =Scorecard!E156 | F8: =Scorecard!F156 | G8: =Scorecard!G156 | H8: =Scorecard!H156 | ... L8: =Scorecard!L156
A9: =Scorecard!A157 | B9: =Scorecard!B157 | C9: =Scorecard!C157 | D9: =Scorecard!D157 | E9: =Scorecard!E157 | F9: =Scorecard!F157 | G9: =Scorecard!G157 | H9: =Scorecard!H157 | ... L9: =Scorecard!L157
A10: =Scorecard!A158 | B10: =Scorecard!B158 | C10: =Scorecard!C158 | D10: =Scorecard!D158 | E10: =Scorecard!E158 | F10: =Scorecard!F158 | G10: =Scorecard!G158 | H10: =Scorecard!H158 | ... L10: =Scorecard!L158
A11: =Scorecard!A159 | B11: =Scorecard!B159 | C11: =Scorecard!C159 | D11: =Scorecard!D159 | E11: =Scorecard!E159 | F11: =Scorecard!F159 | G11: =Scorecard!G159 | H11: =Scorecard!H159 | ... L11: =Scorecard!L159
A12: =Scorecard!A160 | B12: =Scorecard!B160 | C12: =Scorecard!C160 | D12: =Scorecard!D160 | E12: =Scorecard!E160 | F12: =Scorecard!F160 | G12: =Scorecard!G160 | H12: =Scorecard!H160 | ... L12: =Scorecard!L160
A13: =Scorecard!A161 | B13: =Scorecard!B161 | C13: =Scorecard!C161 | D13: =Scorecard!D161 | E13: =Scorecard!E161 | F13: =Scorecard!F161 | G13: =Scorecard!G161 | H13: =Scorecard!H161 | ... L13: =Scorecard!L161
A14: =Scorecard!A162 | B14: =Scorecard!B162 | C14: =Scorecard!C162 | D14: =Scorecard!D162 | E14: =Scorecard!E162 | F14: =Scorecard!F162 | G14: =Scorecard!G162 | H14: =Scorecard!H162 | ... L14: =Scorecard!L162
A15: =Scorecard!A163 | B15: =Scorecard!B163 | C15: =Scorecard!C163 | D15: =Scorecard!D163 | E15: =Scorecard!E163 | F15: =Scorecard!F163 | G15: =Scorecard!G163 | H15: =Scorecard!H163 | ... L15: =Scorecard!L163
A16: =Scorecard!A164 | B16: =Scorecard!B164 | C16: =Scorecard!C164 | D16: =Scorecard!D164 | E16: =Scorecard!E164 | F16: =Scorecard!F164 | G16: =Scorecard!G164 | H16: =Scorecard!H164 | ... L16: =Scorecard!L164
... A27: =Scorecard!A175 | B27: =Scorecard!B175 | C27: =Scorecard!C175 | D27: =Scorecard!D175 | E27: =Scorecard!E175 | F27: =Scorecard!F175 | G27: =Scorecard!G175 | H27: =Scorecard!H175 | ... L27: =Scorecard!L175
A29: Audit tool created by Legion Code Inc. | [LOGO PLACEHOLDER: Legion Code Inc. mark] | https://legioncodeinc.com (placeholder URL, see brand.json note - real brand assets not yet vendored into this repo)

Sheet Search Presence
A1: Search Presence - Detail View
A2: Live-linked view of Scorecard rows 177-199. Edit scores on 'Scorecard'; this sheet mirrors, it does not recompute.
A4: Category | B4: Sub-audit | C4: Leaf ID | D4: Description | E4: Score (0-6) | F4: Evidence pointer | G4: Justification | H4: Weight | I4: Included? | J4: Row type | L4: Rollup %
A5: =Scorecard!A177 | B5: =Scorecard!B177 | C5: =Scorecard!C177 | D5: =Scorecard!D177 | E5: =Scorecard!E177 | F5: =Scorecard!F177 | G5: =Scorecard!G177 | H5: =Scorecard!H177 | ... L5: =Scorecard!L177
A6: =Scorecard!A178 | B6: =Scorecard!B178 | C6: =Scorecard!C178 | D6: =Scorecard!D178 | E6: =Scorecard!E178 | F6: =Scorecard!F178 | G6: =Scorecard!G178 | H6: =Scorecard!H178 | ... L6: =Scorecard!L178
A7: =Scorecard!A179 | B7: =Scorecard!B179 | C7: =Scorecard!C179 | D7: =Scorecard!D179 | E7: =Scorecard!E179 | F7: =Scorecard!F179 | G7: =Scorecard!G179 | H7: =Scorecard!H179 | ... L7: =Scorecard!L179
A8: =Scorecard!A180 | B8: =Scorecard!B180 | C8: =Scorecard!C180 | D8: =Scorecard!D180 | E8: =Scorecard!E180 | F8: =Scorecard!F180 | G8: =Scorecard!G180 | H8: =Scorecard!H180 | ... L8: =Scorecard!L180
A9: =Scorecard!A181 | B9: =Scorecard!B181 | C9: =Scorecard!C181 | D9: =Scorecard!D181 | E9: =Scorecard!E181 | F9: =Scorecard!F181 | G9: =Scorecard!G181 | H9: =Scorecard!H181 | ... L9: =Scorecard!L181
A10: =Scorecard!A182 | B10: =Scorecard!B182 | C10: =Scorecard!C182 | D10: =Scorecard!D182 | E10: =Scorecard!E182 | F10: =Scorecard!F182 | G10: =Scorecard!G182 | H10: =Scorecard!H182 | ... L10: =Scorecard!L182
A11: =Scorecard!A183 | B11: =Scorecard!B183 | C11: =Scorecard!C183 | D11: =Scorecard!D183 | E11: =Scorecard!E183 | F11: =Scorecard!F183 | G11: =Scorecard!G183 | H11: =Scorecard!H183 | ... L11: =Scorecard!L183
A12: =Scorecard!A184 | B12: =Scorecard!B184 | C12: =Scorecard!C184 | D12: =Scorecard!D184 | E12: =Scorecard!E184 | F12: =Scorecard!F184 | G12: =Scorecard!G184 | H12: =Scorecard!H184 | ... L12: =Scorecard!L184
A13: =Scorecard!A185 | B13: =Scorecard!B185 | C13: =Scorecard!C185 | D13: =Scorecard!D185 | E13: =Scorecard!E185 | F13: =Scorecard!F185 | G13: =Scorecard!G185 | H13: =Scorecard!H185 | ... L13: =Scorecard!L185
A14: =Scorecard!A186 | B14: =Scorecard!B186 | C14: =Scorecard!C186 | D14: =Scorecard!D186 | E14: =Scorecard!E186 | F14: =Scorecard!F186 | G14: =Scorecard!G186 | H14: =Scorecard!H186 | ... L14: =Scorecard!L186
A15: =Scorecard!A187 | B15: =Scorecard!B187 | C15: =Scorecard!C187 | D15: =Scorecard!D187 | E15: =Scorecard!E187 | F15: =Scorecard!F187 | G15: =Scorecard!G187 | H15: =Scorecard!H187 | ... L15: =Scorecard!L187
A16: =Scorecard!A188 | B16: =Scorecard!B188 | C16: =Scorecard!C188 | D16: =Scorecard!D188 | E16: =Scorecard!E188 | F16: =Scorecard!F188 | G16: =Scorecard!G188 | H16: =Scorecard!H188 | ... L16: =Scorecard!L188
... A27: =Scorecard!A199 | B27: =Scorecard!B199 | C27: =Scorecard!C199 | D27: =Scorecard!D199 | E27: =Scorecard!E199 | F27: =Scorecard!F199 | G27: =Scorecard!G199 | H27: =Scorecard!H199 | ... L27: =Scorecard!L199
A29: Audit tool created by Legion Code Inc. | [LOGO PLACEHOLDER: Legion Code Inc. mark] | https://legioncodeinc.com (placeholder URL, see brand.json note - real brand assets not yet vendored into this repo)

Sheet Content Score
A1: Content Score - Detail View
A2: Live-linked view of Scorecard rows 201-223. Edit scores on 'Scorecard'; this sheet mirrors, it does not recompute.
A4: Category | B4: Sub-audit | C4: Leaf ID | D4: Description | E4: Score (0-6) | F4: Evidence pointer | G4: Justification | H4: Weight | I4: Included? | J4: Row type | L4: Rollup %
A5: =Scorecard!A201 | B5: =Scorecard!B201 | C5: =Scorecard!C201 | D5: =Scorecard!D201 | E5: =Scorecard!E201 | F5: =Scorecard!F201 | G5: =Scorecard!G201 | H5: =Scorecard!H201 | ... L5: =Scorecard!L201
A6: =Scorecard!A202 | B6: =Scorecard!B202 | C6: =Scorecard!C202 | D6: =Scorecard!D202 | E6: =Scorecard!E202 | F6: =Scorecard!F202 | G6: =Scorecard!G202 | H6: =Scorecard!H202 | ... L6: =Scorecard!L202
A7: =Scorecard!A203 | B7: =Scorecard!B203 | C7: =Scorecard!C203 | D7: =Scorecard!D203 | E7: =Scorecard!E203 | F7: =Scorecard!F203 | G7: =Scorecard!G203 | H7: =Scorecard!H203 | ... L7: =Scorecard!L203
A8: =Scorecard!A204 | B8: =Scorecard!B204 | C8: =Scorecard!C204 | D8: =Scorecard!D204 | E8: =Scorecard!E204 | F8: =Scorecard!F204 | G8: =Scorecard!G204 | H8: =Scorecard!H204 | ... L8: =Scorecard!L204
A9: =Scorecard!A205 | B9: =Scorecard!B205 | C9: =Scorecard!C205 | D9: =Scorecard!D205 | E9: =Scorecard!E205 | F9: =Scorecard!F205 | G9: =Scorecard!G205 | H9: =Scorecard!H205 | ... L9: =Scorecard!L205
A10: =Scorecard!A206 | B10: =Scorecard!B206 | C10: =Scorecard!C206 | D10: =Scorecard!D206 | E10: =Scorecard!E206 | F10: =Scorecard!F206 | G10: =Scorecard!G206 | H10: =Scorecard!H206 | ... L10: =Scorecard!L206
A11: =Scorecard!A207 | B11: =Scorecard!B207 | C11: =Scorecard!C207 | D11: =Scorecard!D207 | E11: =Scorecard!E207 | F11: =Scorecard!F207 | G11: =Scorecard!G207 | H11: =Scorecard!H207 | ... L11: =Scorecard!L207
A12: =Scorecard!A208 | B12: =Scorecard!B208 | C12: =Scorecard!C208 | D12: =Scorecard!D208 | E12: =Scorecard!E208 | F12: =Scorecard!F208 | G12: =Scorecard!G208 | H12: =Scorecard!H208 | ... L12: =Scorecard!L208
A13: =Scorecard!A209 | B13: =Scorecard!B209 | C13: =Scorecard!C209 | D13: =Scorecard!D209 | E13: =Scorecard!E209 | F13: =Scorecard!F209 | G13: =Scorecard!G209 | H13: =Scorecard!H209 | ... L13: =Scorecard!L209
A14: =Scorecard!A210 | B14: =Scorecard!B210 | C14: =Scorecard!C210 | D14: =Scorecard!D210 | E14: =Scorecard!E210 | F14: =Scorecard!F210 | G14: =Scorecard!G210 | H14: =Scorecard!H210 | ... L14: =Scorecard!L210
A15: =Scorecard!A211 | B15: =Scorecard!B211 | C15: =Scorecard!C211 | D15: =Scorecard!D211 | E15: =Scorecard!E211 | F15: =Scorecard!F211 | G15: =Scorecard!G211 | H15: =Scorecard!H211 | ... L15: =Scorecard!L211
A16: =Scorecard!A212 | B16: =Scorecard!B212 | C16: =Scorecard!C212 | D16: =Scorecard!D212 | E16: =Scorecard!E212 | F16: =Scorecard!F212 | G16: =Scorecard!G212 | H16: =Scorecard!H212 | ... L16: =Scorecard!L212
... A27: =Scorecard!A223 | B27: =Scorecard!B223 | C27: =Scorecard!C223 | D27: =Scorecard!D223 | E27: =Scorecard!E223 | F27: =Scorecard!F223 | G27: =Scorecard!G223 | H27: =Scorecard!H223 | ... L27: =Scorecard!L223
A29: Audit tool created by Legion Code Inc. | [LOGO PLACEHOLDER: Legion Code Inc. mark] | https://legioncodeinc.com (placeholder URL, see brand.json note - real brand assets not yet vendored into this repo)

Sheet Findings Register
A1: Findings Register
A2: Every finding, one row each. Populated by audit-scoring-worker-bee from upstream Bees' leaf findings.
A4: Finding ID | B4: Severity | C4: Category | D4: Sub-audit | E4: Page/URL | F4: Evidence | G4: Remediation | H4: Effort (hrs band) | I4: Status
A5: SEC-HEADERS-01 | B5: Critical | C5: Security | D5: Headers | E5: https://example.com/ | F5: example-evidence-pointer.md#L1 | G5: Add Strict-Transport-Security header. | H5: 1-4 | I5: Open
A8: Audit tool created by Legion Code Inc. | [LOGO PLACEHOLDER: Legion Code Inc. mark] | https://legioncodeinc.com (placeholder URL, see brand.json note - real brand assets not yet vendored into this repo)

Sheet Evidence Index
A1: Evidence Index
A2: Artifact map back to the shared audit workspace (build plan section 3).
A4: Evidence ID | B4: Artifact path | C4: Produced by | D4: Captured at | E4: Description
A7: Audit tool created by Legion Code Inc. | [LOGO PLACEHOLDER: Legion Code Inc. mark] | https://legioncodeinc.com (placeholder URL, see brand.json note - real brand assets not yet vendored into this repo)

Sheet Config
A1: Config
A2: Named ranges, version stamp, and generation metadata.
A4: Template version | B4: 1.0.0
A5: Generated at | B5: 2026-08-18 21:18 UTC
A6: Generator script | B6: skills/audit-scoring-stinger/references/scripts/generate-scorecard-xlsx.py
A8: Named ranges
A9: Name | B9: Refers to
A10: CategoryWeights | B10: 'Rubric'!$C$17:$C$24
A11: GradeTable | B11: 'Rubric'!$A$83:$B$92
A12: SecurityOverrideCapPct | B12: 'Rubric'!$B$97
A13: SecurityOverrideEnabled | B13: 'Rubric'!$B$96
A14: SubWt_analytics | B14: 'Rubric'!$C$52:$C$54
A15: SubWt_content | B15: 'Rubric'!$C$76:$C$78
A16: SubWt_foundational | B16: 'Rubric'!$C$64:$C$66
A17: SubWt_mission | B17: 'Rubric'!$C$46:$C$48
A18: SubWt_revenue | B18: 'Rubric'!$C$40:$C$42
A19: SubWt_search | B19: 'Rubric'!$C$70:$C$72
A20: SubWt_security | B20: 'Rubric'!$C$30:$C$36
... A29: Wt_technical | B29: 'Rubric'!$C$21
A32: Audit tool created by Legion Code Inc. | [LOGO PLACEHOLDER: Legion Code Inc. mark] | https://legioncodeinc.com (placeholder URL, see brand.json note - real brand assets not yet vendored into this repo)
